Workbook

Sheet Довідка по заповненню

Sheet Основна
A2: Найменування підприємства (установи, організації)
A3: Національний технічний університет "Харківський політехничний інститут"
A4: Код ЄДРПОУ | B4: 8071187
A6: ОСОБОВА КАРТКА ПРАЦІВНИКА
A8: ЗАГАЛЬНІ ВІДОМОСТІ
A9: Прізвище | C9: =IF('Системна інформація'!D2 = 0, "", 'Системна інформація'!D2)
A10: Ім’я | C10: =IF('Системна інформація'!D3 = 0, "", 'Системна інформація'!D3)
A11: По батькові | C11: =IF('Системна інформація'!D4 = 0, "", 'Системна інформація'!D4)
A12: Дата народження | C12: =IF('Системна інформація'!D5 = 0, "", 'Системна інформація'!D5) | D12: Дата
A13: Громадянство | C13: =IF('Системна інформація'!D6 = 0, "", 'Системна інформація'!D6)
A14: Освіта | C14: =IF('Системна інформація'!D7 = 0, "", 'Системна інформація'!D7) | D14: Список
A15: ППС чи ІТС | C15: =IF('Системна інформація'!D8 = 0, "", 'Системна інформація'!D8) | D15: Список
A16: Науковий ступінь | C16: =IF('Системна інформація'!D9 = 0, "", 'Системна інформація'!D9) | D16: Список на основі БД (Stepen)
A17: Вчене звання | C17: =IF('Системна інформація'!D10 = 0, "", 'Системна інформація'!D10) | D17: Список на основі БД (Zvanie)
A18: Сімейний стан | C18: =IF('Системна інформація'!D11 = 0, "", 'Системна інформація'!D11) | D18: Список
A20: ПОСАДА
A21: Інститут | C21: =IF('Системна інформація'!D12 = 0, "", 'Системна інформація'!D12) | D21: Список на основі БД (Fakultet)
A22: Кафедра (відділ) | C22: =IF('Системна інформація'!D13 = 0, "", 'Системна інформація'!D13) | D22: Список на основі БД (Kafedra)
A23: Посада | C23: =IF('Системна інформація'!D14 = 0, "", 'Системна інформація'!D14) | D23: Список на основі БД (Dolghnost)
A24: Номер наказу про призначення | C24: =IF('Системна інформація'!D15 = 0, "", 'Системна інформація'!D15) | D24: Маска
A25: Дата наказу про призначення | C25: =IF('Системна інформація'!D16 = 0, "", 'Системна інформація'!D16) | D25: Дата
A27: ВІДОМОСТІ ПРО ВІЙСЬКОВИЙ ОБЛІК
A28: Група обліку | C28: =IF('Системна інформація'!D17 = 0, "", 'Системна інформація'!D17) | D28: Список
A29: Категорія обліку | C29: =IF('Системна інформація'!D18 = 0, "", 'Системна інформація'!D18) | D29: Список
A30: Склад | C30: =IF('Системна інформація'!D19 = 0, "", 'Системна інформація'!D19) | D30: Список на основі БД (VSklad)
A31: Військове звання | C31: =IF('Системна інформація'!D20 = 0, "", 'Системна інформація'!D20) | D31: Список на основі БД (Vzvanie)
A32: Військово-облікова спеціальність | C32: =IF('Системна інформація'!D21 = 0, "", 'Системна інформація'!D21) | D32: 6 цифр
A33: Придатність до військової служби | C33: =IF('Системна інформація'!D22 = 0, "", 'Системна інформація'!D22) | D33: Список із додаванням
A34: Териториальний центр комплектування та соціальної підтримки | C34: =IF('Системна інформація'!D23 = 0, "", 'Системна інформація'!D23) | D34: Список на основі БД (Voenkomat) із додаванням

Sheet Адреси Контакти
A1: АДРЕСИ ТА КОНТАКТИ
A3: 11. Місце фактичного проживання
A4: Країна | C4: =IF('Системна інформація'!D24 = 0, "", 'Системна інформація'!D24) | D4: Список на основі БД (Country)
A5: Область (України) | C5: =IF('Системна інформація'!D25 = 0, "", 'Системна інформація'!D25) | D5: Список на основі БД (RegionUkraine) із додаванням
A6: Місто | C6: =IF('Системна інформація'!D26 = 0, "", 'Системна інформація'!D26) | D6: Маска
A7: Адреса (вулиця, № будинку, квартири) | C7: =IF('Системна інформація'!D27 = 0, "", 'Системна інформація'!D27)
A8: Індекс | C8: =IF('Системна інформація'!D28 = 0, "", 'Системна інформація'!D28) | D8: 5 цифр, не обовязкове
A10: Телефони
A11: КОНТАКТНИЙ ТЕЛЕФОН (основний) | C11: =IF('Системна інформація'!D29 = 0, "", 'Системна інформація'!D29) | D11: 10 цифр
A12: КОНТАКТНИЙ ТЕЛЕФОН (додатковий) | C12: =IF('Системна інформація'!D30 = 0, "", 'Системна інформація'!D30) | D12: 10 цифр
A14: 12. Місце проживання за державною реєстрацією
A15: Співпадає із адресою фактичного проживання | C15: =IF('Системна інформація'!D31 = 0, "", 'Системна інформація'!D31) | D15: Список
A17: Країна | C17: =IF('Системна інформація'!D32 = 0, "", 'Системна інформація'!D32) | D17: Список на основі БД (Country)
A18: Область (України) | C18: =IF('Системна інформація'!D33 = 0, "", 'Системна інформація'!D33) | D18: Список на основі БД (RegionUkraine) із додаванням
A19: Місто | C19: =IF('Системна інформація'!D34 = 0, "", 'Системна інформація'!D34) | D19: Маска
A20: Адреса (вулиця, № будинку, квартири) | C20: =IF('Системна інформація'!D35 = 0, "", 'Системна інформація'!D35)
A21: Індекс | C21: =IF('Системна інформація'!D36 = 0, "", 'Системна інформація'!D36) | D21: 5 цифр, не обовязкове

Sheet Освіта
A1: ОСВІТА
A3: 4. ОСВІТА АКАДЕМІЧНА
A4: Назва освітнього закладу | B4: Серія дисплома (свідоцтва) | C4: Номер дисплома (свідоцтва) | D4: Рік закінчення | E4: Спеціальність (професія) за дипломом (свідоцтвом) | F4: Кваліфікація за дипломом (свідоцтвом) | G4: Форма навчання (денна, вечірня, заочна) | H4: Рівень освіти
D9: 4 цифри | G9: Список | H9: Список
A11: 5. ПІСЛЯДИПЛОМНА ПРОФЕСІЙНА ПІДГОТОВКА
A12: Назва освітнього, наукового закладу | B12: Рік закінчення | C12: Рівень підготовки
B19: 4 цифри | C19: Список

Sheet Родина
A1: 10. РОДИННИЙ СТАН
A3: Склад родини
A4: Ступінь родинного зв’язку (склад сім'ї) | B4: Прізвище | C4: Ім’я | D4: По-батькові | E4: Рік народження
A11: Список | E11: 4 цифри!!!

Sheet Документи
A1: ДОКУМЕНТИ
A3: Паспорт (або ID-CARD)
A4: Тип документу | C4: =IF('Системна інформація'!D117 = 0, "", 'Системна інформація'!D117) | D4: Список
A5: Серія та номер | C5: =IF('Системна інформація'!D118 = 0, "", 'Системна інформація'!D118) | D5: Маска: МК229850 або 777111333
A6: Ким виданий | C6: =IF('Системна інформація'!D119 = 0, "", 'Системна інформація'!D119) | D6: Маска для ІД-картки: 4 цирфи
A7: Дата видачі | C7: =IF('Системна інформація'!D120 = 0, "", 'Системна інформація'!D120) | D7: Дата
A9: Військовий квіток
A10: Тип документу | C10: =IF('Системна інформація'!D121 = 0, "", 'Системна інформація'!D121) | D10: Список
A11: Серія та номер | C11: =IF('Системна інформація'!D122 = 0, "", 'Системна інформація'!D122) | D11: Маска: МК224345
A12: Ким виданий | C12: =IF('Системна інформація'!D123 = 0, "", 'Системна інформація'!D123)
A13: Дата видачі | C13: =IF('Системна інформація'!D124 = 0, "", 'Системна інформація'!D124) | D13: Дата
A15: Закордоний паспорт
A16: Серія та номер | C16: =IF('Системна інформація'!D126 = 0, "", 'Системна інформація'!D126) | D16: Маска: FF453210
A17: Ким виданий | C17: =IF('Системна інформація'!D127 = 0, "", 'Системна інформація'!D127) | D17: Маска для ІД-картки: 4 цифри
A18: Дата видачі | C18: =IF('Системна інформація'!D128 = 0, "", 'Системна інформація'!D128) | D18: Дата

Sheet Системна інформація
A1: Назва сторінки | B1: Назва поля | C1: Поле для оновлення | D1: Поле з актуальною інформацією | G1: ОСВІТА АКАДЕМІЧНА | O1: Тип заповнення | P1: Назва списку | Q1: Значення
A2: Основна | B2: =Основна!A9 -> Прізвище | C2: =IF(Основна!B9 = 0, "", Основна!B9) | G2: =OFFSET($D$37,(ROW()-ROW(G$2))*8+(COLUMN()-COLUMN($G2)),0) -> 0 | H2: =OFFSET($D$37,(ROW()-ROW(H$2))*8+(COLUMN()-COLUMN($G2)),0) -> 0 | I2: =OFFSET($D$37,(ROW()-ROW(I$2))*8+(COLUMN()-COLUMN($G2)),0) -> 0 | J2: =OFFSET($D$37,(ROW()-ROW(J$2))*8+(COLUMN()-COLUMN($G2)),0) -> 0 | K2: =OFFSET($D$37,(ROW()-ROW(K$2))*8+(COLUMN()-COLUMN($G2)),0) -> 0 | L2: =OFFSET($D$37,(ROW()-ROW(L$2))*8+(COLUMN()-COLUMN($G2)),0) -> 0 | M2: =OFFSET($D$37,(ROW()-ROW(M$2))*8+(COLUMN()-COLUMN($G2)),0) -> 0 | N2: =OFFSET($D$37,(ROW()-ROW(N$2))*8+(COLUMN()-COLUMN($G2)),0) -> 0 | O2: Визначений | P2: Освіта | Q2: базова загальна середня | R2: повна загальна середня | S2: професійно-технічна | T2: неповна вища | U2: базова вища | V2: повна вища
B3: =Основна!A10 -> Ім’я | C3: =IF(Основна!B10 = 0, "", Основна!B10) | G3: =OFFSET($D$37,(ROW()-ROW(G$2))*8+(COLUMN()-COLUMN($G3)),0) -> 0 | H3: =OFFSET($D$37,(ROW()-ROW(H$2))*8+(COLUMN()-COLUMN($G3)),0) -> 0 | I3: =OFFSET($D$37,(ROW()-ROW(I$2))*8+(COLUMN()-COLUMN($G3)),0) -> 0 | J3: =OFFSET($D$37,(ROW()-ROW(J$2))*8+(COLUMN()-COLUMN($G3)),0) -> 0 | K3: =OFFSET($D$37,(ROW()-ROW(K$2))*8+(COLUMN()-COLUMN($G3)),0) -> 0 | L3: =OFFSET($D$37,(ROW()-ROW(L$2))*8+(COLUMN()-COLUMN($G3)),0) -> 0 | M3: =OFFSET($D$37,(ROW()-ROW(M$2))*8+(COLUMN()-COLUMN($G3)),0) -> 0 | N3: =OFFSET($D$37,(ROW()-ROW(N$2))*8+(COLUMN()-COLUMN($G3)),0) -> 0 | P3: ППС чи ІТС | Q3: НПП | R3: ІТС
B4: =Основна!A11 -> По батькові | C4: =IF(Основна!B11 = 0, "", Основна!B11) | G4: =OFFSET($D$37,(ROW()-ROW(G$2))*8+(COLUMN()-COLUMN($G4)),0) -> 0 | H4: =OFFSET($D$37,(ROW()-ROW(H$2))*8+(COLUMN()-COLUMN($G4)),0) -> 0 | I4: =OFFSET($D$37,(ROW()-ROW(I$2))*8+(COLUMN()-COLUMN($G4)),0) -> 0 | J4: =OFFSET($D$37,(ROW()-ROW(J$2))*8+(COLUMN()-COLUMN($G4)),0) -> 0 | K4: =OFFSET($D$37,(ROW()-ROW(K$2))*8+(COLUMN()-COLUMN($G4)),0) -> 0 | L4: =OFFSET($D$37,(ROW()-ROW(L$2))*8+(COLUMN()-COLUMN($G4)),0) -> 0 | M4: =OFFSET($D$37,(ROW()-ROW(M$2))*8+(COLUMN()-COLUMN($G4)),0) -> 0 | N4: =OFFSET($D$37,(ROW()-ROW(N$2))*8+(COLUMN()-COLUMN($G4)),0) -> 0 | P4: Сімейний стан | Q4: одружений | R4: неодружений | S4: заміжня | T4: незаміжня | U4: розлучений | V4: розлучена | W4: вдова | X4: вдівець
B5: =Основна!A12 -> Дата народження | C5: =IF(Основна!B12 = 0, "", Основна!B12) | G5: =OFFSET($D$37,(ROW()-ROW(G$2))*8+(COLUMN()-COLUMN($G5)),0) -> 0 | H5: =OFFSET($D$37,(ROW()-ROW(H$2))*8+(COLUMN()-COLUMN($G5)),0) -> 0 | I5: =OFFSET($D$37,(ROW()-ROW(I$2))*8+(COLUMN()-COLUMN($G5)),0) -> 0 | J5: =OFFSET($D$37,(ROW()-ROW(J$2))*8+(COLUMN()-COLUMN($G5)),0) -> 0 | K5: =OFFSET($D$37,(ROW()-ROW(K$2))*8+(COLUMN()-COLUMN($G5)),0) -> 0 | L5: =OFFSET($D$37,(ROW()-ROW(L$2))*8+(COLUMN()-COLUMN($G5)),0) -> 0 | M5: =OFFSET($D$37,(ROW()-ROW(M$2))*8+(COLUMN()-COLUMN($G5)),0) -> 0 | N5: =OFFSET($D$37,(ROW()-ROW(N$2))*8+(COLUMN()-COLUMN($G5)),0) -> 0 | P5: Група обліку | Q5: військовозобов'язаний | R5: призовник
B6: =Основна!A13 -> Громадянство | C6: =IF(Основна!B13 = 0, "", Основна!B13) | P6: Категорія обліку | Q6: 1 | R6: 2
B7: =Основна!A14 -> Освіта | C7: =IF(Основна!B14 = 0, "", Основна!B14) | G7: ПІСЛЯДИПЛОМНА ПРОФЕСІЙНА ПІДГОТОВКА | P7: Придатність до військової служби | Q7: придатний | R7: обмежено-придатний | S7: непридатний
B8: =Основна!A15 -> ППС чи ІТС | C8: =IF(Основна!B15 = 0, "", Основна!B15) | G8: =OFFSET($D$69,(ROW()-ROW(G$8))*3+(COLUMN()-COLUMN($G8)),0) -> 0 | H8: =OFFSET($D$69,(ROW()-ROW(H$8))*3+(COLUMN()-COLUMN($G8)),0) -> 0 | I8: =OFFSET($D$69,(ROW()-ROW(I$8))*3+(COLUMN()-COLUMN($G8)),0) -> 0 | P8: Перебування на спеціальному обліку | Q8: Не перебуває
B9: =Основна!A16 -> Науковий ступінь | C9: =IF(Основна!B16 = 0, "", Основна!B16) | G9: =OFFSET($D$69,(ROW()-ROW(G$8))*3+(COLUMN()-COLUMN($G9)),0) -> 0 | H9: =OFFSET($D$69,(ROW()-ROW(H$8))*3+(COLUMN()-COLUMN($G9)),0) -> 0 | I9: =OFFSET($D$69,(ROW()-ROW(I$8))*3+(COLUMN()-COLUMN($G9)),0) -> 0 | P9: Співпадає із адресою фактичного проживання | Q9: ТАК | R9: НІ
B10: =Основна!A17 -> Вчене звання | C10: =IF(Основна!B17 = 0, "", Основна!B17) | G10: =OFFSET($D$69,(ROW()-ROW(G$8))*3+(COLUMN()-COLUMN($G10)),0) -> 0 | H10: =OFFSET($D$69,(ROW()-ROW(H$8))*3+(COLUMN()-COLUMN($G10)),0) -> 0 | I10: =OFFSET($D$69,(ROW()-ROW(I$8))*3+(COLUMN()-COLUMN($G10)),0) -> 0 | P10: Форма навчання (денна, вечірня, заочна) | Q10: Денна | R10: Вечірня | S10: Заочна
B11: =Основна!A18 -> Сімейний стан | C11: =IF(Основна!B18 = 0, "", Основна!B18) | G11: =OFFSET($D$69,(ROW()-ROW(G$8))*3+(COLUMN()-COLUMN($G11)),0) -> 0 | H11: =OFFSET($D$69,(ROW()-ROW(H$8))*3+(COLUMN()-COLUMN($G11)),0) -> 0 | I11: =OFFSET($D$69,(ROW()-ROW(I$8))*3+(COLUMN()-COLUMN($G11)),0) -> 0 | P11: Рівень освіти | Q11: Спеціаліст | R11: Бакалавр | S11: Магістр
B12: =Основна!A21 -> Інститут | C12: =IF(Основна!B21 = 0, "", Основна!B21) | G12: =OFFSET($D$69,(ROW()-ROW(G$8))*3+(COLUMN()-COLUMN($G12)),0) -> 0 | H12: =OFFSET($D$69,(ROW()-ROW(H$8))*3+(COLUMN()-COLUMN($G12)),0) -> 0 | I12: =OFFSET($D$69,(ROW()-ROW(I$8))*3+(COLUMN()-COLUMN($G12)),0) -> 0 | P12: Науковий ступінь, учене звання | Q12: кандидат наук | R12: PhD | S12: доцент | T12: доктор наук | U12: професор
B13: =Основна!A22 -> Кафедра (відділ) | C13: =IF(Основна!B22 = 0, "", Основна!B22) | G13: =OFFSET($D$69,(ROW()-ROW(G$8))*3+(COLUMN()-COLUMN($G13)),0) -> 0 | H13: =OFFSET($D$69,(ROW()-ROW(H$8))*3+(COLUMN()-COLUMN($G13)),0) -> 0 | I13: =OFFSET($D$69,(ROW()-ROW(I$8))*3+(COLUMN()-COLUMN($G13)),0) -> 0 | P13: Рівень підготовки | Q13: аспірантура | R13: ад'юнктура | S13: докторантура
B14: =Основна!A23 -> Посада | C14: =IF(Основна!B23 = 0, "", Основна!B23) | P14: Ступінь родинного зв’язку (склад сім'ї) | Q14: дружина | R14: чоловік | S14: донька | T14: син | U14: донька подружжя | V14: син подружжя
B15: =Основна!A24 -> Номер наказу про призначення | C15: =IF(Основна!B24 = 0, "", Основна!B24) | G15: Склад родини | P15: Тип документу (паспорт) | Q15: Паперовий паспорт | R15: ID картка
B16: =Основна!A25 -> Дата наказу про призначення | C16: =IF(Основна!B25 = 0, "", Основна!B25) | G16: =OFFSET($D$87,(ROW()-ROW(G$16))*5+(COLUMN()-COLUMN($G16)),0) -> 0 | H16: =OFFSET($D$87,(ROW()-ROW(H$16))*5+(COLUMN()-COLUMN($G16)),0) -> 0 | I16: =OFFSET($D$87,(ROW()-ROW(I$16))*5+(COLUMN()-COLUMN($G16)),0) -> 0 | J16: =OFFSET($D$87,(ROW()-ROW(J$16))*5+(COLUMN()-COLUMN($G16)),0) -> 0 | K16: =OFFSET($D$87,(ROW()-ROW(K$16))*5+(COLUMN()-COLUMN($G16)),0) -> 0 | P16: Тип документу (Військовий квіток) | Q16: Військовий квиток | R16: Військовий квиток офіцера запасу
B17: =Основна!A28 -> Група обліку | C17: =IF(Основна!B28 = 0, "", Основна!B28) | G17: =OFFSET($D$87,(ROW()-ROW(G$16))*5+(COLUMN()-COLUMN($G17)),0) -> 0 | H17: =OFFSET($D$87,(ROW()-ROW(H$16))*5+(COLUMN()-COLUMN($G17)),0) -> 0 | I17: =OFFSET($D$87,(ROW()-ROW(I$16))*5+(COLUMN()-COLUMN($G17)),0) -> 0 | J17: =OFFSET($D$87,(ROW()-ROW(J$16))*5+(COLUMN()-COLUMN($G17)),0) -> 0 | K17: =OFFSET($D$87,(ROW()-ROW(K$16))*5+(COLUMN()-COLUMN($G17)),0) -> 0 | O17: З бази даних | P17: Науковий ступінь
B18: =Основна!A29 -> Категорія обліку | C18: =IF(Основна!B29 = 0, "", Основна!B29) | G18: =OFFSET($D$87,(ROW()-ROW(G$16))*5+(COLUMN()-COLUMN($G18)),0) -> 0 | H18: =OFFSET($D$87,(ROW()-ROW(H$16))*5+(COLUMN()-COLUMN($G18)),0) -> 0 | I18: =OFFSET($D$87,(ROW()-ROW(I$16))*5+(COLUMN()-COLUMN($G18)),0) -> 0 | J18: =OFFSET($D$87,(ROW()-ROW(J$16))*5+(COLUMN()-COLUMN($G18)),0) -> 0 | K18: =OFFSET($D$87,(ROW()-ROW(K$16))*5+(COLUMN()-COLUMN($G18)),0) -> 0 | P18: Вчене звання
B19: =Основна!A30 -> Склад | C19: =IF(Основна!B30 = 0, "", Основна!B30) | G19: =OFFSET($D$87,(ROW()-ROW(G$16))*5+(COLUMN()-COLUMN($G19)),0) -> 0 | H19: =OFFSET($D$87,(ROW()-ROW(H$16))*5+(COLUMN()-COLUMN($G19)),0) -> 0 | I19: =OFFSET($D$87,(ROW()-ROW(I$16))*5+(COLUMN()-COLUMN($G19)),0) -> 0 | J19: =OFFSET($D$87,(ROW()-ROW(J$16))*5+(COLUMN()-COLUMN($G19)),0) -> 0 | K19: =OFFSET($D$87,(ROW()-ROW(K$16))*5+(COLUMN()-COLUMN($G19)),0) -> 0 | P19: Інститут
B20: =Основна!A31 -> Військове звання | C20: =IF(Основна!B31 = 0, "", Основна!B31) | G20: =OFFSET($D$87,(ROW()-ROW(G$16))*5+(COLUMN()-COLUMN($G20)),0) -> 0 | H20: =OFFSET($D$87,(ROW()-ROW(H$16))*5+(COLUMN()-COLUMN($G20)),0) -> 0 | I20: =OFFSET($D$87,(ROW()-ROW(I$16))*5+(COLUMN()-COLUMN($G20)),0) -> 0 | J20: =OFFSET($D$87,(ROW()-ROW(J$16))*5+(COLUMN()-COLUMN($G20)),0) -> 0 | K20: =OFFSET($D$87,(ROW()-ROW(K$16))*5+(COLUMN()-COLUMN($G20)),0) -> 0 | P20: Кафедра (відділ)
B21: =Основна!A32 -> Військово-облікова спеціальність | C21: =IF(Основна!B32 = 0, "", Основна!B32) | G21: =OFFSET($D$87,(ROW()-ROW(G$16))*5+(COLUMN()-COLUMN($G21)),0) -> 0 | H21: =OFFSET($D$87,(ROW()-ROW(H$16))*5+(COLUMN()-COLUMN($G21)),0) -> 0 | I21: =OFFSET($D$87,(ROW()-ROW(I$16))*5+(COLUMN()-COLUMN($G21)),0) -> 0 | J21: =OFFSET($D$87,(ROW()-ROW(J$16))*5+(COLUMN()-COLUMN($G21)),0) -> 0 | K21: =OFFSET($D$87,(ROW()-ROW(K$16))*5+(COLUMN()-COLUMN($G21)),0) -> 0 | P21: Посада
B22: =Основна!A33 -> Придатність до військової служби | C22: =IF(Основна!B33 = 0, "", Основна!B33) | P22: Склад
B23: =Основна!A34 -> Териториальний центр комплектування та соціальної підтримки | C23: =IF(Основна!B34 = 0, "", Основна!B34) | P23: Військове звання
A24: Адреси Контакти | B24: ='Адреси Контакти'!A4 -> Країна | C24: =IF('Адреси Контакти'!B4 = 0, "", 'Адреси Контакти'!B4) | P24: Териториальний центр комплектування та соціальної підтримки
B25: ='Адреси Контакти'!A5 -> Область (України) | C25: =IF('Адреси Контакти'!B5 = 0, "", 'Адреси Контакти'!B5) | P25: Країна
B26: ='Адреси Контакти'!A6 -> Місто | C26: =IF('Адреси Контакти'!B6 = 0, "", 'Адреси Контакти'!B6) | P26: Область
B27: ='Адреси Контакти'!A7 -> Адреса (вулиця, № будинку, квартири) | C27: =IF('Адреси Контакти'!B7 = 0, "", 'Адреси Контакти'!B7) | P27: Район (міста)
B28: ='Адреси Контакти'!A8 -> Індекс | C28: =IF('Адреси Контакти'!B8 = 0, "", 'Адреси Контакти'!B8) | P28: Назва освітнього закладу
B29: ='Адреси Контакти'!A11 -> КОНТАКТНИЙ ТЕЛЕФОН (основний) | C29: =IF('Адреси Контакти'!B11 = 0, "", 'Адреси Контакти'!B11)
B30: ='Адреси Контакти'!A12 -> КОНТАКТНИЙ ТЕЛЕФОН (додатковий) | C30: =IF('Адреси Контакти'!B12 = 0, "", 'Адреси Контакти'!B12)
B31: ='Адреси Контакти'!A15 -> Співпадає із адресою фактичного проживання | C31: =IF('Адреси Контакти'!B15 = 0, "", 'Адреси Контакти'!B15)
B32: ='Адреси Контакти'!A17 -> Країна | C32: =IF('Адреси Контакти'!B17 = 0, "", 'Адреси Контакти'!B17)
B33: ='Адреси Контакти'!A18 -> Область (України) | C33: =IF('Адреси Контакти'!B18 = 0, "", 'Адреси Контакти'!B18)
B34: ='Адреси Контакти'!A19 -> Місто | C34: =IF('Адреси Контакти'!B19 = 0, "", 'Адреси Контакти'!B19)
B35: ='Адреси Контакти'!A20 -> Адреса (вулиця, № будинку, квартири) | C35: =IF('Адреси Контакти'!B20 = 0, "", 'Адреси Контакти'!B20)
B36: ='Адреси Контакти'!A21 -> Індекс | C36: =IF('Адреси Контакти'!B21 = 0, "", 'Адреси Контакти'!B21)
A37: Освіта | B37: =Освіта!$A$4 -> Назва освітнього закладу | C37: =IF(Освіта!A5 = 0, "", Освіта!A5)
B38: =Освіта!$B$4 -> Серія дисплома (свідоцтва) | C38: =IF(Освіта!B5 = 0, "", Освіта!B5)
B39: =Освіта!$C$4 -> Номер дисплома (свідоцтва) | C39: =IF(Освіта!C5 = 0, "", Освіта!C5)
B40: =Освіта!$D$4 -> Рік закінчення | C40: =IF(Освіта!D5 = 0, "", Освіта!D5)
...
